<?xml version="1.0" ?>
<robot name="fproject" xmlns:xacro="http://www.ros.org/wiki/xacro">

<xacro:include filename="$(find fproject_description)/urdf/materials.xacro" />
<xacro:include filename="$(find fproject_description)/urdf/fproject.trans" />
<xacro:include filename="$(find fproject_description)/urdf/fproject.gazebo" />
<link name="base_link">
  <inertial>
    <origin xyz="-0.05796760733920991 -0.0012263345459982132 0.062432721134351825" rpy="0 0 0"/>
    <mass value="9.976264079968857"/>
    <inertia ixx="0.065261" iyy="0.117827" izz="0.148661" ixy="-0.001803" iyz="0.000242" ixz="0.011803"/>
  </inertial>
  <visual>
    <origin xyz="0 0 0" rpy="0 0 0"/>
    <geometry>
      <mesh filename="package://fproject_description/meshes/base_link.stl" scale="0.001 0.001 0.001"/>
    </geometry>
    <material name="gray"/>
  </visual>
  <collision>
    <origin xyz="0 0 0" rpy="0 0 0"/>
    <geometry>
      <mesh filename="package://fproject_description/meshes/base_link.stl" scale="0.001 0.001 0.001"/>
    </geometry>
  </collision>
</link>

<link name="body_1_1">
  <inertial>
    <origin xyz="-0.000367308565535005 -0.01662808191141437 0.1823188683811327" rpy="0 0 0"/>
    <mass value="11.497714058301398"/>
    <inertia ixx="0.176105" iyy="0.18006" izz="0.06039" ixy="8.4e-05" iyz="0.014313" ixz="0.000318"/>
  </inertial>
  <visual>
    <origin xyz="0.0 -0.0 -0.1145" rpy="0 0 0"/>
    <geometry>
      <mesh filename="package://fproject_description/meshes/body_1_1.stl" scale="0.001 0.001 0.001"/>
    </geometry>
    <material name="gray_blue"/>
  </visual>
  <collision>
    <origin xyz="0.0 -0.0 -0.1145" rpy="0 0 0"/>
    <geometry>
      <mesh filename="package://fproject_description/meshes/body_1_1.stl" scale="0.001 0.001 0.001"/>
    </geometry>
  </collision>
</link>

<link name="body_2_1">
  <inertial>
    <origin xyz="0.0005838482729470563 -0.007320451707786481 0.09964197410737119" rpy="0 0 0"/>
    <mass value="6.574002541524107"/>
    <inertia ixx="0.088142" iyy="0.090116" izz="0.034433" ixy="0.000203" iyz="0.022651" ixz="0.000128"/>
  </inertial>
  <visual>
    <origin xyz="-0.001068 -0.049088 -0.405" rpy="0 0 0"/>
    <geometry>
      <mesh filename="package://fproject_description/meshes/body_2_1.stl" scale="0.001 0.001 0.001"/>
    </geometry>
    <material name="gray_blue"/>
  </visual>
  <collision>
    <origin xyz="-0.001068 -0.049088 -0.405" rpy="0 0 0"/>
    <geometry>
      <mesh filename="package://fproject_description/meshes/body_2_1.stl" scale="0.001 0.001 0.001"/>
    </geometry>
  </collision>
</link>

<link name="body_3_1">
  <inertial>
    <origin xyz="0.0012098619191938814 0.028094340134804014 0.13050345181878154" rpy="0 0 0"/>
    <mass value="5.351720865390616"/>
    <inertia ixx="0.052634" iyy="0.052607" izz="0.019478" ixy="-6.4e-05" iyz="-0.00863" ixz="-0.000301"/>
  </inertial>
  <visual>
    <origin xyz="-0.00194 4.2e-05 -0.668893" rpy="0 0 0"/>
    <geometry>
      <mesh filename="package://fproject_description/meshes/body_3_1.stl" scale="0.001 0.001 0.001"/>
    </geometry>
    <material name="gray_blue"/>
  </visual>
  <collision>
    <origin xyz="-0.00194 4.2e-05 -0.668893" rpy="0 0 0"/>
    <geometry>
      <mesh filename="package://fproject_description/meshes/body_3_1.stl" scale="0.001 0.001 0.001"/>
    </geometry>
  </collision>
</link>

<link name="body_4_1">
  <inertial>
    <origin xyz="-0.00045697391099836816 -0.03278657661158527 0.0758456470965182" rpy="0 0 0"/>
    <mass value="4.233621983562027"/>
    <inertia ixx="0.041036" iyy="0.042855" izz="0.011567" ixy="3.3e-05" iyz="-0.005539" ixz="2.4e-05"/>
  </inertial>
  <visual>
    <origin xyz="-0.003587 0.001578 -0.894987" rpy="0 0 0"/>
    <geometry>
      <mesh filename="package://fproject_description/meshes/body_4_1.stl" scale="0.001 0.001 0.001"/>
    </geometry>
    <material name="gray_blue"/>
  </visual>
  <collision>
    <origin xyz="-0.003587 0.001578 -0.894987" rpy="0 0 0"/>
    <geometry>
      <mesh filename="package://fproject_description/meshes/body_4_1.stl" scale="0.001 0.001 0.001"/>
    </geometry>
  </collision>
</link>

<link name="body_5_1">
  <inertial>
    <origin xyz="-5.6565592709727826e-05 -0.02158418781731643 0.11395437772919936" rpy="0 0 0"/>
    <mass value="2.436526271475595"/>
    <inertia ixx="0.015014" iyy="0.014924" izz="0.004679" ixy="-4e-06" iyz="0.001893" ixz="7e-06"/>
  </inertial>
  <visual>
    <origin xyz="-0.003129 9.5e-05 -1.133986" rpy="0 0 0"/>
    <geometry>
      <mesh filename="package://fproject_description/meshes/body_5_1.stl" scale="0.001 0.001 0.001"/>
    </geometry>
    <material name="gray_blue"/>
  </visual>
  <collision>
    <origin xyz="-0.003129 9.5e-05 -1.133986" rpy="0 0 0"/>
    <geometry>
      <mesh filename="package://fproject_description/meshes/body_5_1.stl" scale="0.001 0.001 0.001"/>
    </geometry>
  </collision>
</link>

<link name="body_6_1">
  <inertial>
    <origin xyz="-0.00023230986799031373 0.001986271353622778 0.06917875596945255" rpy="0 0 0"/>
    <mass value="2.022663367724799"/>
    <inertia ixx="0.009784" iyy="0.00981" izz="0.004315" ixy="3e-06" iyz="0.002163" ixz="-2.5e-05"/>
  </inertial>
  <visual>
    <origin xyz="-0.002636 -0.015892 -1.314987" rpy="0 0 0"/>
    <geometry>
      <mesh filename="package://fproject_description/meshes/body_6_1.stl" scale="0.001 0.001 0.001"/>
    </geometry>
    <material name="gray_blue"/>
  </visual>
  <collision>
    <origin xyz="-0.002636 -0.015892 -1.314987" rpy="0 0 0"/>
    <geometry>
      <mesh filename="package://fproject_description/meshes/body_6_1.stl" scale="0.001 0.001 0.001"/>
    </geometry>
  </collision>
</link>

<link name="efec_final_1">
  <inertial>
    <origin xyz="0.0022456462663889556 0.0019008715218588415 0.12942756841537562" rpy="0 0 0"/>
    <mass value="2.659020110801838"/>
    <inertia ixx="0.070982" iyy="0.02983" izz="0.091801" ixy="0.001565" iyz="0.000655" ixz="-0.000228"/>
  </inertial>
  <visual>
    <origin xyz="-0.00275 0.000116 -1.481448" rpy="0 0 0"/>
    <geometry>
      <mesh filename="package://fproject_description/meshes/efec_final_1.stl" scale="0.001 0.001 0.001"/>
    </geometry>
    <material name="silver"/>
  </visual>
  <collision>
    <origin xyz="-0.00275 0.000116 -1.481448" rpy="0 0 0"/>
    <geometry>
      <mesh filename="package://fproject_description/meshes/efec_final_1.stl" scale="0.001 0.001 0.001"/>
    </geometry>
  </collision>
</link>

<joint name="joint_1" type="revolute">
  <origin xyz="0.0 0.0 0.1145" rpy="0 0 0"/>
  <parent link="base_link"/>
  <child link="body_1_1"/>
  <axis xyz="0.0 -0.0 1.0"/>
  <limit upper="3.141593" lower="-3.141593" effort="100" velocity="100"/>
</joint>

<joint name="joint_2" type="revolute">
  <origin xyz="0.001068 0.049088 0.2905" rpy="0 0 0"/>
  <parent link="body_1_1"/>
  <child link="body_2_1"/>
  <axis xyz="0.021747 0.999764 0.0"/>
  <limit upper="1.91286" lower="-1.91286" effort="100" velocity="100"/>
</joint>

<joint name="joint_3" type="revolute">
  <origin xyz="0.000872 -0.04913 0.263893" rpy="0 0 0"/>
  <parent link="body_2_1"/>
  <child link="body_3_1"/>
  <axis xyz="0.007351 -0.00016 0.999973"/>
  <limit upper="2.96706" lower="-2.96706" effort="100" velocity="100"/>
</joint>

<joint name="joint_4" type="revolute">
  <origin xyz="0.001647 -0.001536 0.226094" rpy="0 0 0"/>
  <parent link="body_3_1"/>
  <child link="body_4_1"/>
  <axis xyz="-0.009696 -0.999953 -8.9e-05"/>
  <limit upper="2.26892" lower="-2.26892" effort="100" velocity="100"/>
</joint>

<joint name="joint_5" type="revolute">
  <origin xyz="-0.000458 0.001483 0.238999" rpy="0 0 0"/>
  <parent link="body_4_1"/>
  <child link="body_5_1"/>
  <axis xyz="-0.001976 -6.9e-05 0.999998"/>
  <limit upper="3.141593" lower="-3.141593" effort="100" velocity="100"/>
</joint>

<joint name="joint_6" type="revolute">
  <origin xyz="-0.000493 0.015987 0.181001" rpy="0 0 0"/>
  <parent link="body_5_1"/>
  <child link="body_6_1"/>
  <axis xyz="-0.008481 0.999964 5.3e-05"/>
  <limit upper="1.91986" lower="-1.91986" effort="100" velocity="100"/>
</joint>

<joint name="joint_7" type="revolute">
  <origin xyz="0.000114 -0.016008 0.166461" rpy="0 0 0"/>
  <parent link="body_6_1"/>
  <child link="efec_final_1"/>
  <axis xyz="0.001737 -3.8e-05 0.999998"/>
  <limit upper="3.141593" lower="-3.141593" effort="100" velocity="100"/>
</joint>

</robot>
